<?xml version="1.0"?>
<!-- =================================================================================== -->
<!-- |    This document was autogenerated by xacro from awcombo.xacro                  | -->
<!-- |    EDITING THIS FILE BY HAND IS NOT RECOMMENDED                                 | -->
<!-- =================================================================================== -->
<robot name="awcombo">
  <material name="aluminum">
    <color rgba="0.5 0.5 0.5 1" />
  </material>
  <material name="plastic">
    <color rgba="0.1 0.1 0.1 1" />
  </material>

  <gazebo reference="lidar_1_link">
    <sensor name="lidar_1_sensor" type="ray">
      <always_on>true</always_on>
      <pose>0 0 0 0 0 0</pose>
      <visualize>false</visualize>
      <update_rate>40</update_rate>
      <ray>
        <scan>
          <horizontal>
            <samples>720</samples>
            <resolution>1</resolution>
            <min_angle>-1.48</min_angle>
            <max_angle>1.48</max_angle>
          </horizontal>
        </scan>
        <range>
          <min>0.10</min>
          <max>30.0</max>
          <resolution>0.05</resolution>
        </range>
        <noise>
          <type>gaussian</type>
          <!-- Noise parameters based on published spec for Hokuyo laser
                   achieving "+-30mm" accuracy at range < 10m.  A mean of 0.0m and
                   stddev of 0.01m will put 99.7% of samples within 0.03m of the true
                   reading. -->
          <mean>0.0</mean>
          <stddev>0.01</stddev>
        </noise>
      </ray>
      <plugin filename="libgazebo_ros_ray_sensor.so" name="lidar_1">
        <ros>
          <!-- <namespace>   </namespace> -->
          <argument>~/out:=scan</argument>
        </ros>
        <!-- Set output to sensor_msgs/LaserScan to get same output type as gazebo_ros_laser -->
        <output_type>sensor_msgs/LaserScan</output_type>
        <frame_name>lidar_1_link</frame_name>
      </plugin>
    </sensor>
  </gazebo>

  <gazebo reference="lidar_2_link">
    <sensor name="lidar_2_sensor" type="ray">
      <pose>0 0 0 0 0 0</pose>
      <visualize>false</visualize>
      <update_rate>40</update_rate>
      <ray>
        <scan>
          <horizontal>
            <samples>720</samples>
            <resolution>1</resolution>
            <min_angle>-1.48</min_angle>
            <max_angle>1.48</max_angle>
          </horizontal>
        </scan>
        <range>
          <min>0.10</min>
          <max>30.0</max>
          <resolution>0.05</resolution>
        </range>
        <noise>
          <type>gaussian</type>
          <!-- Noise parameters based on published spec for Hokuyo laser
                   achieving "+-30mm" accuracy at range < 10m.  A mean of 0.0m and
                   stddev of 0.01m will put 99.7% of samples within 0.03m of the true
                   reading. -->
          <mean>0.0</mean>
          <stddev>0.01</stddev>
        </noise>
      </ray>
      <plugin filename="libgazebo_ros_ray_sensor.so" name="lidar_2">
        <ros>
          <!-- <namespace> </namespace> -->
          <argument>~/out:=scan2</argument>
        </ros>
        <!-- Set output to sensor_msgs/LaserScan to get same output type as gazebo_ros_laser -->
        <output_type>sensor_msgs/LaserScan</output_type>
        <frame_name>lidar_2_link</frame_name>
      </plugin>
    </sensor>
  </gazebo>

  <gazebo>
    <plugin name="object_controller" filename="libgazebo_ros_planar_move.so">

      <commandTopic>cmd_vel</commandTopic>
      <odometryTopic>odom</odometryTopic>
      <robotNamespace>
        <remapping>/tf:=tf</remapping>
      </robotNamespace>
      <ros>
        <remapping>/tf:=tf</remapping>
      </ros>

      <!-- Set control loop update rate -->
      <odometryRate>100</odometryRate>
      <!-- Set odom publish rate -->
      <publish_rate>100</publish_rate>

      <!-- Set if odom required -->
      <publish_odom>true</publish_odom>
      <publish_odom_tf>true</publish_odom_tf>

      <!-- Frame IDs -->
      <odometryFrame>odom</odometryFrame>
      <robotBaseFrame>base_link</robotBaseFrame>

      <!-- Set odom covariance -->
      <covariance_x>0.0001</covariance_x>
      <covariance_y>0.0001</covariance_y>
      <covariance_yaw>0.0001</covariance_yaw>

    </plugin>
  </gazebo>

  <!-- camera -->
  <gazebo reference="camera_link">

    <sensor type="depth" name="camera_link">

      <always_on>1</always_on>

      <update_rate>15</update_rate>

      <camera name="camera_link"> ... <distortion>
          <k1>0.1</k1>
          <k2>0.2</k2>
          <k3>0.3</k3>
          <p1>0.4</p1>
          <p2>0.5</p2>
          <center>0.5 0.5</center>
        </distortion>
      </camera>

      <plugin name="camera_link" filename="libgazebo_ros_camera.so">

        <ros>
        </ros>

        <camera_name> </camera_name>

        <frame_name> </frame_name>

        <hack_baseline>0.07</hack_baseline>


        <min_depth>0.001</min_depth>
        <max_depth>300.0</max_depth>
      </plugin>
    </sensor>
  </gazebo>

  <link name="base_link">
    <inertial>
      <origin rpy="0 0 0" xyz="0.00020197 0.0019401 0.43265" />
      <mass value="95.371" />
      <inertia ixx="7.048" ixy="0.0020566" ixz="-0.00016602" iyy="7.0414" iyz="-0.14914"
        izz="12.614" />
    </inertial>
    <visual>
      <origin rpy="0 0 0" xyz="0 0 0" />
      <geometry>
        <mesh
          filename="package://amr_combo_v2/meshes/base_link.STL" />
      </geometry>
      <material name="">
        <color rgba="0.77647 0.75686 0.73725 1" />
      </material>
    </visual>
    <collision>
      <origin rpy="0 0 0" xyz="0 0 0" />
      <geometry>
        <mesh
          filename="package://amr_combo_v2/meshes/base_link.STL" />
      </geometry>
    </collision>
  </link>
  <link name="base_footprint">
    <inertial>
      <origin rpy="0 0 0" xyz="-0.00097233 0.00030419 0.2973" />
      <mass value="27.996" />
      <inertia ixx="1.2308" ixy="-0.00018417" ixz="1.2244E-06" iyy="1.1622" iyz="9.0657E-07"
        izz="2.3922" />
    </inertial>
    <visual>
      <origin rpy="0 0 0" xyz="0 0 0" />
      <geometry>
        <mesh
          filename="package://amr_combo_v2/meshes/base_footprint.STL" />
      </geometry>
      <material name="">
        <color rgba="0.86667 0.86667 0.8902 1" />
      </material>
    </visual>
    <collision>
      <origin rpy="0 0 0" xyz="0 0 0" />
      <geometry>
        <mesh
          filename="package://amr_combo_v2/meshes/base_footprint.STL" />
      </geometry>
    </collision>
  </link>
  <joint name="base_footprint_joint" type="fixed">
    <origin rpy="0 0 0" xyz="0 0 0" />
    <parent link="base_link" />
    <child link="base_footprint" />
    <axis xyz="0 0 0" />
  </joint>
  <link name="mpo_700_caster_back_left_link">
    <inertial>
      <origin rpy="0 0 0" xyz="-5.5511E-17 0.0079242 -0.027057" />
      <mass value="17.529" />
      <inertia ixx="0.15365" ixy="4.3519E-19" ixz="2.079E-18" iyy="0.15493" iyz="0.010987"
        izz="0.025283" />
    </inertial>
    <visual>
      <origin rpy="0 0 0" xyz="0 0 0" />
      <geometry>
        <mesh
          filename="package://amr_combo_v2/meshes/mpo_700_caster_back_left_link.STL" />
      </geometry>
      <material name="">
        <color rgba="0.77647 0.75686 0.73725 1" />
      </material>
    </visual>
    <collision>
      <origin rpy="0 0 0" xyz="0 0 0" />
      <geometry>
        <mesh
          filename="package://amr_combo_v2/meshes/mpo_700_caster_back_left_link.STL" />
      </geometry>
    </collision>
  </link>
  <joint name="mpo_700_caster_back_left_joint" type="revolute">
    <origin rpy="0 0 0" xyz="-0.26 0.26 0.22" />
    <parent link="base_footprint" />
    <child link="mpo_700_caster_back_left_link" />
    <axis xyz="0 0 1" />
    <limit effort="1000" lower="-1E+16" upper="1E+16" velocity="6.5" />
    <dynamics damping="30" friction="110" />
  </joint>
  <link name="mpo_700_wheel_back_left_link">
    <inertial>
      <origin rpy="0 0 0" xyz="0 -0.0003764 0" />
      <mass value="5.9448" />
      <inertia ixx="0.012415" ixy="-1.6832E-19" ixz="-6.1901E-19" iyy="0.02381" iyz="-1.5948E-18"
        izz="0.012415" />
    </inertial>
    <visual>
      <origin rpy="0 0 0" xyz="0 0 0" />
      <geometry>
        <mesh
          filename="package://amr_combo_v2/meshes/mpo_700_wheel_back_left_link.STL" />
      </geometry>
      <material name="">
        <color rgba="0.77647 0.75686 0.73725 1" />
      </material>
    </visual>
    <collision>
      <origin rpy="0 0 0" xyz="0 0 0" />
      <geometry>
        <mesh
          filename="package://amr_combo_v2/meshes/mpo_700_wheel_back_left_link.STL" />
      </geometry>
    </collision>
  </link>
  <joint name="mpo_700_wheel_back_left_joint" type="revolute">
    <origin rpy="0 0 3.1416" xyz="0 -0.0453 -0.122" />
    <parent link="mpo_700_caster_back_left_link" />
    <child link="mpo_700_wheel_back_left_link" />
    <axis xyz="0 1 0" />
    <limit effort="1000" lower="-1E+16" upper="1E+16" velocity="20.5" />
    <dynamics damping="30" friction="110" />
  </joint>
  <link name="mpo_700_caster_back_right_link">
    <inertial>
      <origin rpy="0 0 0" xyz="0 0.0079242 -0.027057" />
      <mass value="17.529" />
      <inertia ixx="0.15365" ixy="6.5122E-20" ixz="1.2755E-18" iyy="0.15493" iyz="0.010987"
        izz="0.025283" />
    </inertial>
    <visual>
      <origin rpy="0 0 0" xyz="0 0 0" />
      <geometry>
        <mesh
          filename="package://amr_combo_v2/meshes/mpo_700_caster_back_right_link.STL" />
      </geometry>
      <material name="">
        <color rgba="0.77647 0.75686 0.73725 1" />
      </material>
    </visual>
    <collision>
      <origin rpy="0 0 0" xyz="0 0 0" />
      <geometry>
        <mesh
          filename="package://amr_combo_v2/meshes/mpo_700_caster_back_right_link.STL" />
      </geometry>
    </collision>
  </link>
  <joint name="mpo_700_caster_back_right_joint" type="revolute">
    <origin rpy="0 0 0" xyz="-0.26 -0.26 0.22" />
    <parent link="base_footprint" />
    <child link="mpo_700_caster_back_right_link" />
    <axis xyz="0 0 1" />
    <limit effort="1000" lower="-1E+16" upper="1E+16" velocity="6.5" />
    <dynamics damping="30" friction="110" />
  </joint>
  <link name="mpo_700_wheel_back_right_link">
    <inertial>
      <origin rpy="0 0 0" xyz="0 -0.0003764 -2.7756E-17" />
      <mass value="5.9448" />
      <inertia ixx="0.012415" ixy="-1.0996E-19" ixz="-6.1905E-19" iyy="0.02381" iyz="1.0833E-19"
        izz="0.012415" />
    </inertial>
    <visual>
      <origin rpy="0 0 0" xyz="0 0 0" />
      <geometry>
        <mesh
          filename="package://amr_combo_v2/meshes/mpo_700_wheel_back_right_link.STL" />
      </geometry>
      <material name="">
        <color rgba="0.77647 0.75686 0.73725 1" />
      </material>
    </visual>
    <collision>
      <origin rpy="0 0 0" xyz="0 0 0" />
      <geometry>
        <mesh
          filename="package://amr_combo_v2/meshes/mpo_700_wheel_back_right_link.STL" />
      </geometry>
    </collision>
  </link>
  <joint name="mpo_700_wheel_back_right_joint" type="revolute">
    <origin rpy="0 0 3.1416" xyz="0 -0.0453 -0.122" />
    <parent link="mpo_700_caster_back_right_link" />
    <child link="mpo_700_wheel_back_right_link" />
    <axis xyz="0 -1 0" />
    <limit effort="1000" lower="-1E+16" upper="1E+16" velocity="20.5" />
    <dynamics damping="30" friction="110" />
  </joint>
  <link name="mpo_700_caster_front_left_link">
    <inertial>
      <origin rpy="0 0 0" xyz="0 0.0079242 -0.027057" />
      <mass value="17.529" />
      <inertia ixx="0.15365" ixy="7.7938E-19" ixz="-1.1941E-18" iyy="0.15493" iyz="0.010987"
        izz="0.025283" />
    </inertial>
    <visual>
      <origin rpy="0 0 0" xyz="0 0 0" />
      <geometry>
        <mesh
          filename="package://amr_combo_v2/meshes/mpo_700_caster_front_left_link.STL" />
      </geometry>
      <material name="">
        <color rgba="0.77647 0.75686 0.73725 1" />
      </material>
    </visual>
    <collision>
      <origin rpy="0 0 0" xyz="0 0 0" />
      <geometry>
        <mesh
          filename="package://amr_combo_v2/meshes/mpo_700_caster_front_left_link.STL" />
      </geometry>
    </collision>
  </link>
  <joint name="mpo_700_caster_front_left_joint" type="revolute">
    <origin rpy="0 0 0" xyz="0.26 0.26 0.22" />
    <parent link="base_footprint" />
    <child link="mpo_700_caster_front_left_link" />
    <axis xyz="0 0 1" />
    <limit effort="1000" lower="-1E+16" upper="1E+16" velocity="6.5" />
    <dynamics damping="30" friction="110" />
  </joint>
  <link name="mpo_700_wheel_front_left_link">
    <inertial>
      <origin rpy="0 0 0" xyz="0 -0.0003764 1.3878E-17" />
      <mass value="5.9448" />
      <inertia ixx="0.012415" ixy="-3.9576E-19" ixz="-2.0189E-19" iyy="0.02381" iyz="-1.7678E-18"
        izz="0.012415" />
    </inertial>
    <visual>
      <origin rpy="0 0 0" xyz="0 0 0" />
      <geometry>
        <mesh
          filename="package://amr_combo_v2/meshes/mpo_700_wheel_front_left_link.STL" />
      </geometry>
      <material name="">
        <color rgba="0.77647 0.75686 0.73725 1" />
      </material>
    </visual>
    <collision>
      <origin rpy="0 0 0" xyz="0 0 0" />
      <geometry>
        <mesh
          filename="package://amr_combo_v2/meshes/mpo_700_wheel_front_left_link.STL" />
      </geometry>
    </collision>
  </link>
  <joint name="mpo_700_wheel_front_left_joint" type="revolute">
    <origin rpy="0 0 3.1416" xyz="0 -0.0453 -0.122" />
    <parent link="mpo_700_caster_front_left_link" />
    <child link="mpo_700_wheel_front_left_link" />
    <axis xyz="0 1 0" />
    <limit effort="10000" lower="-1E+16" upper="1E+16" velocity="20.5" />
    <dynamics damping="30" friction="110" />
  </joint>
  <link name="mpo_700_caster_front_right_link">
    <inertial>
      <origin rpy="0 0 0" xyz="0 0.0079242 -0.027057" />
      <mass value="17.529" />
      <inertia ixx="0.15365" ixy="4.224E-19" ixz="-7.1236E-19" iyy="0.15493" iyz="0.010987"
        izz="0.025283" />
    </inertial>
    <visual>
      <origin rpy="0 0 0" xyz="0 0 0" />
      <geometry>
        <mesh
          filename="package://amr_combo_v2/meshes/mpo_700_caster_front_right_link.STL" />
      </geometry>
      <material name="">
        <color rgba="0.77647 0.75686 0.73725 1" />
      </material>
    </visual>
    <collision>
      <origin rpy="0 0 0" xyz="0 0 0" />
      <geometry>
        <mesh
          filename="package://amr_combo_v2/meshes/mpo_700_caster_front_right_link.STL" />
      </geometry>
    </collision>
  </link>
  <joint name="mpo_700_caster_front_right_joint" type="revolute">
    <origin rpy="0 0 0" xyz="0.26 -0.26 0.22" />
    <parent link="base_footprint" />
    <child link="mpo_700_caster_front_right_link" />
    <axis xyz="0 0 1" />
    <limit effort="1000" lower="-1E+16" upper="1E+16" velocity="6.5" />
    <dynamics damping="30" friction="110" />
  </joint>
  <link name="mpo_700_wheel_front_right_link">
    <inertial>
      <origin rpy="0 0 0" xyz="0 -0.0003764 -2.7756E-17" />
      <mass value="5.9448" />
      <inertia ixx="0.012415" ixy="-1.2506E-19" ixz="-2.0193E-19" iyy="0.02381" iyz="-6.4764E-20"
        izz="0.012415" />
    </inertial>
    <visual>
      <origin rpy="0 0 0" xyz="0 0 0" />
      <geometry>
        <mesh
          filename="package://amr_combo_v2/meshes/mpo_700_wheel_front_right_link.STL" />
      </geometry>
      <material name="">
        <color rgba="0.77647 0.75686 0.73725 1" />
      </material>
    </visual>
    <collision>
      <origin rpy="0 0 0" xyz="0 0 0" />
      <geometry>
        <mesh
          filename="package://amr_combo_v2/meshes/mpo_700_wheel_front_right_link.STL" />
      </geometry>
    </collision>
  </link>
  <joint name="mpo_700_wheel_front_right_joint" type="revolute">
    <origin rpy="0 0 -3.1416" xyz="0 -0.0453 -0.122" />
    <parent link="mpo_700_caster_front_right_link" />
    <child link="mpo_700_wheel_front_right_link" />
    <axis xyz="0 -1 0" />
    <limit effort="1000" lower="-1E+16" upper="1E+16" velocity="20.5" />
    <dynamics damping="30" friction="110" />
  </joint>
  <link name="lidar_1_link">
    <inertial>
      <origin rpy="0 0 0" xyz="-1.0182 1.7996E-06 0.01114" />
      <mass value="0.28899" />
      <inertia ixx="0.00020547" ixy="-1.0914E-08" ixz="1.1185E-08" iyy="0.00020546" iyz="1.6374E-08"
        izz="0.0002783" />
    </inertial>
    <visual>
      <origin rpy="0 0 0" xyz="0 0 0" />
      <geometry>
        <mesh
          filename="package://amr_combo_v2/meshes/lidar_1_link.STL" />
      </geometry>
      <material name="">
        <color rgba="0.79216 0.81961 0.93333 1" />
      </material>
    </visual>
    <collision>
      <origin rpy="0 0 0" xyz="0 0 0" />
      <geometry>
        <mesh
          filename="package://amr_combo_v2/meshes/lidar_1_link.STL" />
      </geometry>
    </collision>
  </link>
  <joint name="lidar_1_link" type="fixed">
    <origin rpy="3.1416 0 -2.3562" xyz="-0.36 -0.36 0.2465" />
    <parent link="base_link" />
    <child link="lidar_1_link" />
    <axis xyz="0 0 0" />
  </joint>
  <link name="lidar_2_link">
    <inertial>
      <origin rpy="0 0 0" xyz="-1.0182 -1.6443E-06 0.01114" />
      <mass value="0.28899" />
      <inertia ixx="0.00020547" ixy="-1.1651E-08" ixz="-1.3037E-08" iyy="0.00020547"
        iyz="-1.4942E-08" izz="0.0002783" />
    </inertial>
    <visual>
      <origin rpy="0 0 0" xyz="0 0 0" />
      <geometry>
        <mesh
          filename="package://amr_combo_v2/meshes/lidar_2_link.STL" />
      </geometry>
      <material name="">
        <color rgba="0.79216 0.81961 0.93333 1" />
      </material>
    </visual>
    <collision>
      <origin rpy="0 0 0" xyz="0 0 0" />
      <geometry>
        <mesh
          filename="package://amr_combo_v2/meshes/lidar_2_link.STL" />
      </geometry>
    </collision>
  </link>
  <joint name="lidar_2_link" type="fixed">
    <origin rpy="3.1416 0 0.7854" xyz="0.36 0.36 0.2465" />
    <parent link="base_link" />
    <child link="lidar_2_link" />
    <axis xyz="0 0 0" />
  </joint>
  <link name="agv_link1">
    <inertial>
      <origin rpy="0 0 0" xyz="-1.0093E-18 0 -0.43855" />
      <mass value="150.55" />
      <inertia ixx="17.026" ixy="-1.9211E-17" ixz="4.6799E-16" iyy="17.026" iyz="5.5226E-17"
        izz="0.54086" />
    </inertial>
    <visual>
      <origin rpy="0 0 0" xyz="0 0 0" />
      <geometry>
        <mesh
          filename="package://amr_combo_v2/meshes/agv_link1.STL" />
      </geometry>
      <material name="">
        <color rgba="0.77647 0.75686 0.73725 1" />
      </material>
    </visual>
    <collision>
      <origin rpy="0 0 0" xyz="0 0 0" />
      <geometry>
        <mesh
          filename="package://amr_combo_v2/meshes/agv_link1.STL" />
      </geometry>
    </collision>
  </link>
  <joint name="agv_link1" type="fixed">
    <origin rpy="0 0 0" xyz="0 -0.237 1.446" />
    <parent link="base_link" />
    <child link="agv_link1" />
    <axis xyz="0 0 0" />
  </joint>
  <joint name="awtube2_18kg_v2_base_joint" type="fixed">
    <parent link="agv_link1" />
    <child link="awtube2_18kg_v2_base_link" />
    <origin rpy="0 0 0" xyz="0 0 0" />
  </joint>
  <link name="awtube2_18kg_v2_base_link">
    <inertial>
      <origin rpy="0 0 0" xyz="3.1408E-18 2.3265E-19 0.011306" />
      <mass value="0.71698" />
      <inertia ixx="0.0026347" ixy="-3.4047E-19" ixz="3.6583E-20" iyy="0.0026347" iyz="3.3614E-20"
        izz="0.0051879" />
    </inertial>
    <visual>
      <origin rpy="0 0 0" xyz="0 0 0" />
      <geometry>
        <mesh
          filename="package://awtube2_18kg_v2/meshes/base_link.STL" />
      </geometry>
      <material name="">
        <color rgba="0.79216 0.81961 0.93333 1" />
      </material>
    </visual>
    <collision>
      <origin rpy="0 0 0" xyz="0 0 0" />
      <geometry>
        <mesh
          filename="package://awtube2_18kg_v2/meshes/controllo/base_link.STL" />
      </geometry>
    </collision>
  </link>
  <link name="awtube2_18kg_v2_link1">
    <inertial>
      <origin rpy="0 0 0" xyz="-5.6964E-08 0.0052032 0.13467" />
      <mass value="7.4558" />
      <inertia ixx="0.059839" ixy="-9.5174E-08" ixz="1.4852E-07" iyy="0.057912" iyz="0.0017444"
        izz="0.034054" />
    </inertial>
    <visual>
      <origin rpy="0 0 0" xyz="0 0 0" />
      <geometry>
        <mesh
          filename="package://awtube2_18kg_v2/meshes/link1.STL" />
      </geometry>
      <material name="">
        <color rgba="0.79216 0.81961 0.93333 1" />
      </material>
    </visual>
    <collision>
      <origin rpy="0 0 0" xyz="0 0 0" />
      <geometry>
        <mesh
          filename="package://awtube2_18kg_v2/meshes/controllo/link1.STL" />
      </geometry>
    </collision>
  </link>
  <joint name="awtube2_18kg_v2_joint1" type="revolute">
    <origin rpy="0 0 1.5707963267948966" xyz="0 0 0.025" />
    <parent link="awtube2_18kg_v2_base_link" />
    <child link="awtube2_18kg_v2_link1" />
    <axis xyz="0 0 -1" />
    <limit effort="600" lower="-3.14" upper="3.14" velocity="1.2436" />
    <dynamics damping="1" friction="0.1" />
  </joint>
  <link name="awtube2_18kg_v2_link2">
    <inertial>
      <origin rpy="0 0 0" xyz="3.0744E-16 0.34153 0.17206" />
      <mass value="16.867" />
      <inertia ixx="0.13028" ixy="-1.9035E-07" ixz="-2.5941E-17" iyy="0.12157" iyz="-5.8547E-18"
        izz="0.080528" />
    </inertial>
    <visual>
      <origin rpy="0 0 0" xyz="0 0 0" />
      <geometry>
        <mesh
          filename="package://awtube2_18kg_v2/meshes/link2.STL" />
      </geometry>
      <material name="">
        <color rgba="0.79216 0.81961 0.93333 1" />
      </material>
    </visual>
    <collision>
      <origin rpy="0 0 0" xyz="0 0 0" />
      <geometry>
        <mesh
          filename="package://awtube2_18kg_v2/meshes/controllo/link2.STL" />
      </geometry>
    </collision>
  </link>
  <joint name="awtube2_18kg_v2_joint2" type="revolute">
    <origin rpy="1.5708 0 3.1416" xyz="0 0.1045 0.09" />
    <parent link="awtube2_18kg_v2_link1" />
    <child link="awtube2_18kg_v2_link2" />
    <axis xyz="0 0 -1" />
    <limit effort="650" lower="-3.14" upper="3.14" velocity="0.86" />
    <dynamics damping="1" friction="0.100" />
  </joint>
  <link name="awtube2_18kg_v2_link3">
    <inertial>
      <origin rpy="0 0 0" xyz="1.0739E-07 -0.031501 0.12478" />
      <mass value="5.2778" />
      <inertia ixx="0.027836" ixy="-2.6227E-09" ixz="2.1362E-09" iyy="0.014296" iyz="0.0014164"
        izz="0.0285" />
    </inertial>
    <visual>
      <origin rpy="0 0 0" xyz="0 0 0" />
      <geometry>
        <mesh
          filename="package://awtube2_18kg_v2/meshes/link3.STL" />
      </geometry>
      <material name="">
        <color rgba="0.79216 0.81961 0.93333 1" />
      </material>
    </visual>
    <collision>
      <origin rpy="0 0 0" xyz="0 0 0" />
      <geometry>
        <mesh
          filename="package://awtube2_18kg_v2/meshes/controllo/link3.STL" />
      </geometry>
    </collision>
  </link>
  <joint name="awtube2_18kg_v2_joint3" type="revolute">
    <origin rpy="3.1416 0 -1.5707963267948966" xyz="0 0.725 0.0495" />
    <parent link="awtube2_18kg_v2_link2" />
    <child link="awtube2_18kg_v2_link3" />
    <axis xyz="0 0 -1" />
    <limit effort="350" lower="-3.14" upper="3.14" velocity="1.24" />
    <dynamics damping="1" friction="0.1" />
  </joint>
  <link name="awtube2_18kg_v2_link4">
    <inertial>
      <origin rpy="0 0 0" xyz="1.1453E-07 -0.033596 0.53855" />
      <mass value="4.9487" />
      <inertia ixx="0.03104" ixy="-2.6227E-09" ixz="2.1362E-09" iyy="0.0175" iyz="0.0014164"
        izz="0.026027" />
    </inertial>
    <visual>
      <origin rpy="0 0 0" xyz="0 0 0" />
      <geometry>
        <mesh
          filename="package://awtube2_18kg_v2/meshes/link4.STL" />
      </geometry>
      <material name="">
        <color rgba="0.79216 0.81961 0.93333 1" />
      </material>
    </visual>
    <collision>
      <origin rpy="0 0 0" xyz="0 0 0" />
      <geometry>
        <mesh
          filename="package://awtube2_18kg_v2/meshes/controllo/link4.STL" />
      </geometry>
    </collision>
  </link>
  <joint name="awtube2_18kg_v2_joint4" type="revolute">
    <origin rpy="-1.5708 0 0" xyz="0 0.0874 0.154" />
    <parent link="awtube2_18kg_v2_link3" />
    <child link="awtube2_18kg_v2_link4" />
    <axis xyz="0 0 -1" />
    <limit effort="145" lower="-3.14" upper="3.14" velocity="2.71" />
    <dynamics damping="1" friction="0.1" />
  </joint>
  <link name="awtube2_18kg_v2_link5">
    <inertial>
      <origin rpy="0 0 0" xyz="4.1585E-08 -0.17645 -0.055943" />
      <mass value="3.3765" />
      <inertia ixx="0.016413" ixy="-2.9318E-08" ixz="-3.1693E-09" iyy="0.0061497" iyz="2.9588E-05"
        izz="0.017107" />
    </inertial>
    <visual>
      <origin rpy="0 0 0" xyz="0 0 0" />
      <geometry>
        <mesh
          filename="package://awtube2_18kg_v2/meshes/link5.STL" />
      </geometry>
      <material name="">
        <color rgba="0.79216 0.81961 0.93333 1" />
      </material>
    </visual>
    <collision>
      <origin rpy="0 0 0" xyz="0 0 0" />
      <geometry>
        <mesh
          filename="package://awtube2_18kg_v2/meshes/controllo/link5.STL" />
      </geometry>
    </collision>
  </link>
  <joint name="awtube2_18kg_v2_joint5" type="revolute">
    <origin rpy="-1.5708 1.5707963267948966 0" xyz="0 0.0924 0.5876" />
    <parent link="awtube2_18kg_v2_link4" />
    <child link="awtube2_18kg_v2_link5" />
    <axis xyz="0 0 -1" />
    <limit effort="145" lower="-1.6" upper="1.6" velocity="2.71" />
    <dynamics damping="1" friction="0.1" />
  </joint>
  <link name="awtube2_18kg_v2_link6">
    <inertial>
      <origin rpy="0 0 0" xyz="1.721E-16 -1.7268E-16 0.027662" />
      <mass value="0.382" />
      <inertia ixx="0.0003488" ixy="9.2314E-20" ixz="4.3131E-20" iyy="0.0003488" iyz="-7.1296E-20"
        izz="0.00054908" />
    </inertial>
    <visual>
      <origin rpy="0 0 0" xyz="0 0 0" />
      <geometry>
        <mesh
          filename="package://awtube2_18kg_v2/meshes/link6.STL" />
      </geometry>
      <material name="">
        <color rgba="0.79216 0.81961 0.93333 1" />
      </material>
    </visual>
    <collision>
      <origin rpy="0 0 0" xyz="0 0 0" />
      <geometry>
        <mesh
          filename="package://awtube2_18kg_v2/meshes/controllo/link6.STL" />
      </geometry>
    </collision>
  </link>
  <joint name="awtube2_18kg_v2_joint6" type="revolute">
    <origin rpy="1.5708 0 0" xyz="0 -0.2975 -0.0924" />
    <parent link="awtube2_18kg_v2_link5" />
    <child link="awtube2_18kg_v2_link6" />
    <axis xyz="0 0 -1" />
    <limit effort="85" lower="-3.14" upper="3.14" velocity="3.61" />
    <dynamics damping="1" friction="0.1" />
  </joint>
  <joint name="grip_exon_base_joint" type="fixed">
    <parent link="awtube2_18kg_v2_link6" />
    <child link="RIF" />
    <origin rpy="0 0 -1.57" xyz="0 0 0.057" />
  </joint>
  <link name="RIF">
    <inertial>
      <origin rpy="0 0 0" xyz="0.00021269 2.1562E-14 0.0025" />
      <mass value="0.02908" />
      <inertia ixx="8.9458E-06" ixy="1.4285E-18" ixz="-4.9596E-21" iyy="2.8336E-05" iyz="1.2484E-18"
        izz="3.7163E-05" />
    </inertial>
    <visual>
      <origin rpy="0 0 0" xyz="0 0 0" />
      <geometry>
        <mesh
          filename="package://grip_exon/meshes/RIF.STL" />
      </geometry>
      <material name="">
        <color rgba="0.79216 0.81961 0.93333 1" />
      </material>
    </visual>
    <collision>
      <origin rpy="0 0 0" xyz="0 0 0" />
      <geometry>
        <mesh
          filename="package://grip_exon/meshes/RIF.STL" />
      </geometry>
    </collision>
  </link>
  <link name="GRIPPER">
    <inertial>
      <origin rpy="0 0 0" xyz="0.00070773 -0.00049669 -0.043144" />
      <mass value="0.69541" />
      <inertia ixx="0.001292" ixy="-3.4933E-08" ixz="-1.1642E-07" iyy="0.0030317" iyz="1.7201E-06"
        izz="0.0041665" />
    </inertial>
    <visual>
      <origin rpy="0 0 0" xyz="0 0 0" />
      <geometry>
        <mesh
          filename="package://grip_exon/meshes/GRIPPER.STL" />
      </geometry>
      <material name="">
        <color rgba="0.79216 0.81961 0.93333 1" />
      </material>
    </visual>
    <collision>
      <origin rpy="0 0 0" xyz="0 0 0" />
      <geometry>
        <mesh
          filename="package://grip_exon/meshes/GRIPPER.STL" />
      </geometry>
    </collision>
  </link>
  <joint name="GRIPPER" type="fixed">
    <origin rpy="0 0 0" xyz="0 0 0.1211" />
    <parent link="RIF" />
    <child link="GRIPPER" />
    <axis xyz="0 0 0" />
  </joint>
  <joint name="supporto_cam_base_joint" type="fixed">
    <parent link="GRIPPER" />
    <child link="base" />
    <origin rpy="3.14 0 1.57" xyz="0 -0.08 -0.048" />
  </joint>
  <link name="base">
    <inertial>
      <origin rpy="0 0 0" xyz="-0.024968 -1.2433E-07 0.023136" />
      <mass value="0.080064" />
      <inertia ixx="3.9197E-05" ixy="1.1651E-10" ixz="9.4191E-06" iyy="4.1104E-05" iyz="-1.2673E-10"
        izz="6.4713E-05" />
    </inertial>
    <visual>
      <origin rpy="0 0 0" xyz="0 0 0" />
      <geometry>
        <mesh
          filename="package://camera_support/meshes/base.STL" />
      </geometry>
      <material name="">
        <color rgba="0.69804 0.69804 0.69804 1" />
      </material>
    </visual>
    <collision>
      <origin rpy="0 0 0" xyz="0 0 0" />
      <geometry>
        <mesh
          filename="package://camera_support/meshes/base.STL" />
      </geometry>
    </collision>
  </link>
  <link name="cam">
    <inertial>
      <origin rpy="0 0 0" xyz="-5E-05 -4.3708E-19 0" />
      <mass value="1E-07" />
      <inertia ixx="1.6667E-14" ixy="-4.7178E-34" ixz="-5.2119E-32" iyy="8.4167E-15"
        iyz="-1.5126E-30" izz="8.4167E-15" />
    </inertial>
    <visual>
      <origin rpy="0 0 0" xyz="0 0 0" />
      <geometry>
        <mesh
          filename="package://camera_support/meshes/cam.STL" />
      </geometry>
      <material name="">
        <color rgba="0.79216 0.81961 0.93333 1" />
      </material>
    </visual>
    <collision>
      <origin rpy="0 0 0" xyz="0 0 0" />
      <geometry>
        <mesh
          filename="package://camera_support/meshes/cam.STL" />
      </geometry>
    </collision>
  </link>
  <joint name="cam" type="fixed">
    <origin rpy="0 1.5708 0" xyz="-0.0645 0 0.0259" />
    <parent link="base" />
    <child link="cam" />
    <axis xyz="0 0 0" />
  </joint>
  <!-- camera body, with origin at bottom screw mount -->
  <joint name="camera_joint" type="fixed">
    <origin rpy="3.14 0 0" xyz="0.01 0 0.0125" />
    <parent link="cam" />
    <child link="camera_bottom_screw_frame" />
  </joint>
  <link name="camera_bottom_screw_frame" />
  <joint name="camera_link_joint" type="fixed">
    <origin rpy="0 0 0" xyz="0.010600000000000002 0.0175 0.0125" />
    <parent link="camera_bottom_screw_frame" />
    <child link="camera_link" />
  </joint>
  <link name="camera_link">
    <visual>
      <!-- the mesh origin is at front plate in between the two infrared camera axes -->
      <origin rpy="1.5707963267948966 0 1.5707963267948966" xyz="0.0043 -0.0175 0" />
      <geometry>
        <mesh
          filename="package://realsense_description/meshes/d435.dae" />
      </geometry>
    </visual>
    <collision>
      <origin rpy="0 0 0" xyz="0 -0.0175 0" />
      <geometry>
        <box size="0.02505 0.09 0.025" />
      </geometry>
    </collision>
    <inertial>
      <!-- The following are not reliable values, and should not be used for modeling -->
      <mass value="0.072" />
      <origin xyz="0 0 0" />
      <inertia ixx="0.003881243" ixy="0.0" ixz="0.0" iyy="0.000498940" iyz="0.0" izz="0.003879257" />
    </inertial>
  </link>

  <ros2_control name="awtube" type="system">
    <hardware>
      <plugin>gazebo_ros2_control/GazeboSystem</plugin>
      <!-- <plugin>fake_components/GenericSystem</plugin> -->
      <param name="interface_name">eno1</param>
      <param name="cpu_id">0</param>
      <param name="control_frequency">100</param>
    </hardware>
    <!-- GPIO -->
    <!-- <gpio name="Beckhoff">
      <command_interface name="dig_output.1" />
      <command_interface name="dig_output.2" />
      <command_interface name="dig_output.3" />
      <command_interface name="dig_output.4" />
      <command_interface name="dig_output.5" />
      <command_interface name="dig_output.6" />
      <command_interface name="dig_output.7" />
      <command_interface name="dig_output.8" />
      <state_interface name="dig_output.1" />
      <state_interface name="dig_output.2" />
      <state_interface name="dig_output.3" />
      <state_interface name="dig_output.4" />
      <state_interface name="dig_output.5" />
      <state_interface name="dig_output.6" />
      <state_interface name="dig_output.7" />
      <state_interface name="dig_output.8" />
      <state_interface name="dig_input.1" />
      <state_interface name="dig_input.2" />
      <state_interface name="dig_input.3" />
      <state_interface name="dig_input.4" />
      <state_interface name="dig_input.5" />
      <state_interface name="dig_input.6" />
      <state_interface name="dig_input.7" />
      <state_interface name="dig_input.8" />
      <ec_module name="EK1100">
        <plugin>ethercat/BeckhoffEK1100</plugin>
        <param name="client_id">1</param>
      </ec_module>
      <ec_module name="EL1808">
        <plugin>ethercat/BeckhoffEL1808</plugin>
        <param name="client_id">2</param>
        <param name="di.1">dig_input.1</param>
        <param name="di.2">dig_input.2</param>
        <param name="di.3">dig_input.3</param>
        <param name="di.4">dig_input.4</param>
        <param name="di.5">dig_input.5</param>
        <param name="di.6">dig_input.6</param>
        <param name="di.7">dig_input.7</param>
        <param name="di.8">dig_input.8</param>
      </ec_module>
      <ec_module name="EL2808">
        <plugin>ethercat/BeckhoffEL2808</plugin>
        <param name="client_id">3</param>
        <param name="do.1">dig_output.1</param>
        <param name="do.2">dig_output.2</param>
        <param name="do.3">dig_output.3</param>
        <param name="do.4">dig_output.4</param>
        <param name="do.5">dig_output.5</param>
        <param name="do.6">dig_output.6</param>
        <param name="do.7">dig_output.7</param>
        <param name="do.8">dig_output.8</param>
      </ec_module>
    </gpio> -->
    <!-- Joints -->
    <joint name="awtube2_18kg_v2_joint1">
      <command_interface name="position" />
      <!-- <command_interface name="velocity" />
      <command_interface name="effort" /> -->
      <state_interface name="position" />
      <!-- <state_interface name="velocity" />
      <state_interface name="effort" /> -->
      <!-- <ec_module name="AWJointClient">
        <plugin>ethercat/AWJointClient</plugin>
        <param name="client_id">4</param>
        <param name="mode_of_operation">CSP</param>
      </ec_module> -->
    </joint>
    <joint name="awtube2_18kg_v2_joint2">
      <command_interface name="position" />
      <!-- <command_interface name="velocity" />
      <command_interface name="effort" /> -->
      <state_interface name="position" />
      <!-- <state_interface name="velocity" />
      <state_interface name="effort" /> -->
      <!-- <ec_module name="AWJointClient">
        <plugin>ethercat/AWJointClient</plugin>
        <param name="client_id">5</param>
        <param name="mode_of_operation">CSP</param>
      </ec_module> -->
    </joint>
    <joint name="awtube2_18kg_v2_joint3">
      <command_interface name="position" />
      <!-- <command_interface name="velocity" />
      <command_interface name="effort" /> -->
      <state_interface name="position" />
      <!-- <state_interface name="velocity" />
      <state_interface name="effort" /> -->
      <!-- <ec_module name="AWJointClient">
        <plugin>ethercat/AWJointClient</plugin>
        <param name="client_id">6</param>
        <param name="mode_of_operation">CSP</param>
      </ec_module> -->
    </joint>
    <joint name="awtube2_18kg_v2_joint4">
      <command_interface name="position" />
      <!-- <command_interface name="velocity" />
      <command_interface name="effort" /> -->
      <state_interface name="position" />
      <!-- <state_interface name="velocity" />
      <state_interface name="effort" /> -->
      <!-- <ec_module name="AWJointClient">
        <plugin>ethercat/AWJointClient</plugin>
        <param name="client_id">7</param>
        <param name="mode_of_operation">CSP</param>
      </ec_module> -->
    </joint>
    <joint name="awtube2_18kg_v2_joint5">
      <command_interface name="position" />
      <!-- <command_interface name="velocity" />
      <command_interface name="effort" /> -->
      <state_interface name="position" />
      <!-- <state_interface name="velocity" />
      <state_interface name="effort" /> -->
      <!-- <ec_module name="AWJointClient">
        <plugin>ethercat/AWJointClient</plugin>
        <param name="client_id">8</param>
        <param name="mode_of_operation">CSP</param>
      </ec_module> -->
    </joint>
    <joint name="awtube2_18kg_v2_joint6">
      <command_interface name="position" />
      <!-- <command_interface name="velocity" />
      <command_interface name="effort" /> -->
      <state_interface name="position" />
      <!-- <state_interface name="velocity" />
      <state_interface name="effort" /> -->
      <!-- <ec_module name="AWJointClient">
        <plugin>ethercat/AWJointClient</plugin>
        <param name="client_id">9</param>
        <param name="mode_of_operation">CSP</param>
      </ec_module> -->
    </joint>

    <!-- <transmission name="tran1">
      <plugin>transmission_interface/SimpleTransmission</plugin>
      <joint name="awtube2_18kg_v2_joint1" role="awtube2_18kg_v2_joint1">
        <hardwareInterface>JointStateInterface</hardwareInterface>
      </joint>
      <actuator name="motor1" role="motor1">
        <hardwareInterface>JointStateInterface</hardwareInterface>
        <mechanicalReduction>1</mechanicalReduction>
      </actuator>
    </transmission>

    <transmission name="tran2">
      <plugin>transmission_interface/SimpleTransmission</plugin>
      <joint name="awtube2_18kg_v2_joint2" role="awtube2_18kg_v2_joint2">
        <hardwareInterface>JointStateInterface</hardwareInterface>
      </joint>
      <actuator name="motor2" role="motor2">
        <hardwareInterface>JointStateInterface</hardwareInterface>
        <mechanicalReduction>1</mechanicalReduction>
      </actuator>
    </transmission>  -->

    <!--  <transmission name="tran3">
      <plugin>transmission_interface/SimpleTransmission</plugin>
      <joint name="awtube2_18kg_v2_joint3" role="awtube2_18kg_v2_joint3">
        <hardwareInterface>JointStateInterface</hardwareInterface>
      </joint>
      <actuator name="motor3" role="motor3">
        <hardwareInterface>JointStateInterface</hardwareInterface>
        <mechanicalReduction>1</mechanicalReduction>
      </actuator>
    </transmission>

    <transmission name="tran4">
      <plugin>transmission_interface/SimpleTransmission</plugin>
      <joint name="awtube2_18kg_v2_joint4" role="awtube2_18kg_v2_joint4">
        <hardwareInterface>JointStateInterface</hardwareInterface>
      </joint>
      <actuator name="motor4" role="motor4">
        <hardwareInterface>JointStateInterface</hardwareInterface>
        <mechanicalReduction>1</mechanicalReduction>
      </actuator>
    </transmission>

    <transmission name="tran5">
      <plugin>transmission_interface/SimpleTransmission</plugin>
      <joint name="awtube2_18kg_v2_joint5" role="awtube2_18kg_v2_joint5">
        <hardwareInterface>JointStateInterface</hardwareInterface>
      </joint>
      <actuator name="motor5" role="motor5">
        <hardwareInterface>JointStateInterface</hardwareInterface>
        <mechanicalReduction>1</mechanicalReduction>
      </actuator>
    </transmission>

    <transmission name="tran6">
      <plugin>transmission_interface/SimpleTransmission</plugin>
      <joint name="awtube2_18kg_v2_joint6" role="awtube2_18kg_v2_joint6">
        <hardwareInterface>JointStateInterface</hardwareInterface>
      </joint>
      <actuator name="motor6" role="motor6">
        <hardwareInterface>JointStateInterface</hardwareInterface>
        <mechanicalReduction>1</mechanicalReduction>
      </actuator>
     </transmission> -->

  </ros2_control>

  <gazebo reference="mpo_700_wheel_front_right_link">
    <!-- <kp> 10000 </kp> -->
    <!-- <fdir1>0 1 0</fdir1> -->
    <!-- <slip1> 0.1 </slip1> -->
    <mu1>0.0001</mu1>
    <mu2>0.0001</mu2>
  </gazebo>

  <gazebo reference="mpo_700_wheel_back_right_link">
    <!-- <kp> 10000 </kp> -->
    <!-- <fdir1>0 1 0</fdir1> -->
    <!-- <slip1> 0.1 </slip1> -->
    <mu1>0.0001</mu1>
    <mu2>0.0001</mu2>
  </gazebo>

  <gazebo reference="mpo_700_wheel_front_left_link">
    <!-- <kp> 10000 </kp> -->
    <!-- <fdir1>0 1 0</fdir1> -->
    <!-- <slip1> 0.1 </slip1> -->
    <mu1>0.0001</mu1>
    <mu2>0.0001</mu2>
  </gazebo>

  <gazebo reference="mpo_700_wheel_back_left_link">
    <!-- <kp> 10000 </kp> -->
    <!-- <fdir1>0 1 0</fdir1> -->
    <!-- <slip1> 0.1 </slip1> -->
    <mu1>0.0001</mu1>
    <mu2>0.0001</mu2>
  </gazebo>

  <gazebo>
    <plugin name="gazebo_ros2_control" filename="libgazebo_ros2_control.so">
      <!-- <robotNamespace>/</robotNamespace> -->
      <!-- ROS 2 Control Parameters -->
      <!-- <controlPeriod>0.01</controlPeriod> -->
      <!--
      <parameters>filename="package:=//neo_simulation2/robots/mpo_700/meshes/awcombo.ros2_controllers.yaml"</parameters> -->
      <!-- <parameters>$(find
      neo_simulation2)/robots/mpo_700/meshes/awcombo.ros2_controllers.yaml</parameters> -->
      <!-- <parameters>robots/mpo_700/meshes/awcombo.ros2_controllers.yaml</parameters> -->
      <!--
      /home/progettista6/awCombo_simulation/install/neo_simulation2/share/neo_simulation2/robots/mpo_700/meshes/descriptions/awcombo_description -->
      <!--
      <parameters>/neo_simulation2/share/neo_simulation2/configs/mpo_700/awcombo.ros2_controllers.yaml</parameters> -->
      <parameters>
        /home/progettista6/awCombo_simulation/src/descriptions/awcombo_description/config/awcombo.ros2_controllers.yaml</parameters>
    </plugin>
  </gazebo>

</robot>