<?xml version="1.0" encoding="utf-8"?>
<!-- This URDF was automatically created by SolidWorks to URDF Exporter! Originally created by Stephen Brawner (brawner@gmail.com) 
     Commit Version: 1.5.1-0-g916b5db  Build Version: 1.5.7152.31018
     For more information, please see http://wiki.ros.org/sw_urdf_exporter -->
<robot
  name="awtube2">
  <link
    name="base_link">
    <inertial>
      <origin
        xyz="3.1408E-18 2.3265E-19 0.011306"
        rpy="0 0 0" />
      <mass
        value="0.71698" />
      <inertia
        ixx="0.0026347"
        ixy="-3.4047E-19"
        ixz="3.6583E-20"
        iyy="0.0026347"
        iyz="3.3614E-20"
        izz="0.0051879" />
    </inertial>
    <visual>
      <origin
        xyz="0 0 0"
        rpy="0 0 0" />
      <geometry>
        <mesh
          filename="package://awtube2_18kg_v2/meshes/base_link.STL" />
      </geometry>
      <material
        name="">
        <color
          rgba="0.79216 0.81961 0.93333 1" />
      </material>
    </visual>
    <collision>
      <origin
        xyz="0 0 0"
        rpy="0 0 0" />
      <geometry>
        <mesh
          filename="package://awtube2_18kg_v2/meshes/controllo/base_link.STL" />
      </geometry>
    </collision>
  </link>
  <link
    name="link1">
    <inertial>
      <origin
        xyz="-5.6964E-08 0.0052032 0.13467"
        rpy="0 0 0" />
      <mass
        value="7.4558" />
      <inertia
        ixx="0.059839"
        ixy="-9.5174E-08"
        ixz="1.4852E-07"
        iyy="0.057912"
        iyz="0.0017444"
        izz="0.034054" />
    </inertial>
    <visual>
      <origin
        xyz="0 0 0"
        rpy="0 0 0" />
      <geometry>
        <mesh
          filename="package://awtube2_18kg_v2/meshes/link1.STL" />
      </geometry>
      <material
        name="">
        <color
          rgba="0.79216 0.81961 0.93333 1" />
      </material>
    </visual>
    <collision>
      <origin
        xyz="0 0 0"
        rpy="0 0 0" />
      <geometry>
        <mesh
          filename="package://awtube2_18kg_v2/meshes/controllo/link1.STL" />
      </geometry>
    </collision>
  </link>
  <joint
    name="joint1"
    type="revolute">
    <origin
      xyz="0 0 0.025"
      rpy="0 0 0" />
    <parent
      link="base_link" />
    <child
      link="link1" />
    <axis
      xyz="0 0 -1" />
    <limit
      lower="-3.14"
      upper="3.14"
      effort="600"
      velocity="1.2436" />
    <dynamics
      damping="1"
      friction="0.1" />
  </joint>
  <link
    name="link2">
    <inertial>
      <origin
        xyz="3.0744E-16 0.34153 0.17206"
        rpy="0 0 0" />
      <mass
        value="16.867" />
      <inertia
        ixx="0.13028"
        ixy="-1.9035E-07"
        ixz="-2.5941E-17"
        iyy="0.12157"
        iyz="-5.8547E-18"
        izz="0.080528" />
    </inertial>
    <visual>
      <origin
        xyz="0 0 0"
        rpy="0 0 0" />
      <geometry>
        <mesh
          filename="package://awtube2_18kg_v2/meshes/link2.STL" />
      </geometry>
      <material
        name="">
        <color
          rgba="0.79216 0.81961 0.93333 1" />
      </material>
    </visual>
    <collision>
      <origin
        xyz="0 0 0"
        rpy="0 0 0" />
      <geometry>
        <mesh
          filename="package://awtube2_18kg_v2/meshes/controllo/link2.STL" />
      </geometry>
    </collision>
  </link>
  <joint
    name="joint2"
    type="revolute">
    <origin
      xyz="0 0.1045 0.09"
      rpy="1.5708 0 3.1416" />
    <parent
      link="link1" />
    <child
      link="link2" />
    <axis
      xyz="0 0 -1" />
    <limit
      lower="-3.14"
      upper="3.14"
      effort="650"
      velocity="0.86" />
    <dynamics
      damping="1"
      friction="0.1" />
  </joint>
  <link
    name="link3">
    <inertial>
      <origin
        xyz="1.0739E-07 -0.031501 0.12478"
        rpy="0 0 0" />
      <mass
        value="5.2778" />
      <inertia
        ixx="0.027836"
        ixy="-2.6227E-09"
        ixz="2.1362E-09"
        iyy="0.014296"
        iyz="0.0014164"
        izz="0.0285" />
    </inertial>
    <visual>
      <origin
        xyz="0 0 0"
        rpy="0 0 0" />
      <geometry>
        <mesh
          filename="package://awtube2_18kg_v2/meshes/link3.STL" />
      </geometry>
      <material
        name="">
        <color
          rgba="0.79216 0.81961 0.93333 1" />
      </material>
    </visual>
    <collision>
      <origin
        xyz="0 0 0"
        rpy="0 0 0" />
      <geometry>
        <mesh
          filename="package://awtube2_18kg_v2/meshes/controllo/link3.STL" />
      </geometry>
    </collision>
  </link>
  <joint
    name="joint3"
    type="revolute">
    <origin
      xyz="0 0.725 0.0495"
      rpy="3.1416 0 -3.1416" />
    <parent
      link="link2" />
    <child
      link="link3" />
    <axis
      xyz="0 0 -1" />
    <limit
      lower="-3.14"
      upper="3.14"
      effort="350"
      velocity="1.24" />
    <dynamics
      damping="1"
      friction="0.1" />
  </joint>
  <link
    name="link4">
    <inertial>
      <origin
        xyz="1.1453E-07 -0.033596 0.53855"
        rpy="0 0 0" />
      <mass
        value="4.9487" />
      <inertia
        ixx="0.03104"
        ixy="-2.6227E-09"
        ixz="2.1362E-09"
        iyy="0.0175"
        iyz="0.0014164"
        izz="0.026027" />
    </inertial>
    <visual>
      <origin
        xyz="0 0 0"
        rpy="0 0 0" />
      <geometry>
        <mesh
          filename="package://awtube2_18kg_v2/meshes/link4.STL" />
      </geometry>
      <material
        name="">
        <color
          rgba="0.79216 0.81961 0.93333 1" />
      </material>
    </visual>
    <collision>
      <origin
        xyz="0 0 0"
        rpy="0 0 0" />
      <geometry>
        <mesh
          filename="package://awtube2_18kg_v2/meshes/controllo/link4.STL" />
      </geometry>
    </collision>
  </link>
  <joint
    name="joint4"
    type="revolute">
    <origin
      xyz="0 0.0874 0.154"
      rpy="-1.5708 0 0" />
    <parent
      link="link3" />
    <child
      link="link4" />
    <axis
      xyz="0 0 -1" />
    <limit
      lower="-3.14"
      upper="3.14"
      effort="145"
      velocity="2.71" />
    <dynamics
      damping="1"
      friction="0.1" />
  </joint>
  <link
    name="link5">
    <inertial>
      <origin
        xyz="4.1585E-08 -0.17645 -0.055943"
        rpy="0 0 0" />
      <mass
        value="3.3765" />
      <inertia
        ixx="0.016413"
        ixy="-2.9318E-08"
        ixz="-3.1693E-09"
        iyy="0.0061497"
        iyz="2.9588E-05"
        izz="0.017107" />
    </inertial>
    <visual>
      <origin
        xyz="0 0 0"
        rpy="0 0 0" />
      <geometry>
        <mesh
          filename="package://awtube2_18kg_v2/meshes/link5.STL" />
      </geometry>
      <material
        name="">
        <color
          rgba="0.79216 0.81961 0.93333 1" />
      </material>
    </visual>
    <collision>
      <origin
        xyz="0 0 0"
        rpy="0 0 0" />
      <geometry>
        <mesh
          filename="package://awtube2_18kg_v2/meshes/controllo/link5.STL" />
      </geometry>
    </collision>
  </link>
  <joint
    name="joint5"
    type="revolute">
    <origin
      xyz="0 0.0924 0.5876"
      rpy="-1.5708 0 0" />
    <parent
      link="link4" />
    <child
      link="link5" />
    <axis
      xyz="0 0 -1" />
    <limit
      lower="-1.6"
      upper="1.6"
      effort="145"
      velocity="2.71" />
    <dynamics
      damping="1"
      friction="0.1" />
  </joint>
  <link
    name="link6">
    <inertial>
      <origin
        xyz="1.721E-16 -1.7268E-16 0.027662"
        rpy="0 0 0" />
      <mass
        value="0.382" />
      <inertia
        ixx="0.0003488"
        ixy="9.2314E-20"
        ixz="4.3131E-20"
        iyy="0.0003488"
        iyz="-7.1296E-20"
        izz="0.00054908" />
    </inertial>
    <visual>
      <origin
        xyz="0 0 0"
        rpy="0 0 0" />
      <geometry>
        <mesh
          filename="package://awtube2_18kg_v2/meshes/link6.STL" />
      </geometry>
      <material
        name="">
        <color
          rgba="0.79216 0.81961 0.93333 1" />
      </material>
    </visual>
    <collision>
      <origin
        xyz="0 0 0"
        rpy="0 0 0" />
      <geometry>
        <mesh
          filename="package://awtube2_18kg_v2/meshes/controllo/link6.STL" />
      </geometry>
    </collision>
  </link>
  <joint
    name="joint6"
    type="revolute">
    <origin
      xyz="0 -0.2975 -0.0924"
      rpy="1.5708 0 0" />
    <parent
      link="link5" />
    <child
      link="link6" />
    <axis
      xyz="0 0 -1" />
    <limit
      lower="-3.14"
      upper="3.14"
      effort="85"
      velocity="3.61" />
    <dynamics
      damping="1"
      friction="0.1" />
  </joint>
</robot>
